Workbook

Sheet Dashboard
B1: Dashboard – coûts mensuels de la migration IKS → ROKS
B2: Données recalculées automatiquement depuis Synthèse. La courbe suit l'horizon défini dans Paramètres & ABS.
B3: ="Périmètre affiché : "&C8 -> Périmètre affiché : Tous
B4: Coût total | D4: Coût IKS | F4: Coût ROKS | H4: Surcoût double run | J4: Écart vs sans migration | L4: Contrôles
B5: =SUMIFS(TblCalculs[Coût mensuel],TblCalculs[Environnement],p_envcrit) -> 1364404 | D5: =SUMIFS(TblCalculs[Coût mensuel],TblCalculs[Plateforme],"IKS",TblCalculs[Environnement],p_envcrit) -> 524628 | F5: =SUMIFS(TblCalculs[Coût mensuel],TblCalculs[Plateforme],"ROKS",TblCalculs[Environnement],p_envcrit) -> 839776 | H5: =SUMIFS(TblCalculs[Coût mensuel],TblCalculs[Environnement],p_envcrit)-SUMIFS(TblCalculs[Sans DR – coût],TblCalculs[Environnement],p_envcrit) -> 51507 | J5: =SUMIFS(TblCalculs[Coût mensuel],TblCalculs[Environnement],p_envcrit)-SUMIFS(TblCalculs[Sans migration – coût],TblCalculs[Environnement],p_envcrit) -> -183020 | L5: =Synthèse!C17 -> OK – aucune anomalie
B7: Période : | C7: =CHOOSE(MONTH(p_debut),"janv.","févr.","mars","avr.","mai","juin","juil.","août","sept.","oct.","nov.","déc.")&" "&YEAR(p_debut)&" → "&CHOOSE(MONTH(p_fin),"janv.","févr.","mars","avr.","mai","juin","juil.","août","sept.","oct.","nov.","déc.")&" "&YEAR(p_fin)&" ("&p_horizon&" mois)" -> oct. 2026 → sept. 2029 (36 mois)
B8: Environnement : | C8: Tous | D8: =IF(C8="Tous","*",C8) -> * | E8: ← Tous / PRD / NPRD : filtre les indicateurs et la courbe
B36: Lecture : l'écart entre la courbe IKS qui baisse et ROKS qui monte matérialise la bascule ; la courbe verte montre le surcoût des mois payés en double (double run).
B37: Toutes les courbes sont en € par mois, sur le même axe.
B39: Répartition des coûts par tribe et par domaine (horizon, périmètre du filtre C8)
B40: Coût des clusters : | D40: =SUMIFS(TblCalculs[Coût mensuel],TblCalculs[Environnement],p_envcrit) -> 1364404 | F40: Affecté aux déploiements : | H40: =SUMIFS(TblApplications[Coût total affecté (€)],TblApplications[Environnement],p_envcrit) -> 722062.29 | J40: Socle / non affecté : | L40: =D40-H40 -> 642341.71
B41: Clé : ROKS dès le provisionnement selon le besoin (vCPU + poids × Go) ; IKS jusqu'à la libération selon les ressources libérables. Socle = capacité initiale et planchers non attribués.
B62: Tribe | C62: Domaine | D62: Coût IKS € | E62: Coût ROKS € | F62: Coût total € | I62: Domaine | J62: Coût IKS € | K62: Coût ROKS € | L62: Coût total €
B63: =IFERROR(IF(INDEX(TblTribes[Tribe],1)="","",INDEX(TblTribes[Tribe],1)),"") -> Parcours client | C63: =IF($B63="","",INDEX(TblTribes[Domaine de la tribe],1)) -> Distribution | D63: =IF($B63="","",SUMIFS(TblApplications[Coût IKS affecté (€)],TblApplications[Tribe],$B63,TblApplications[Environnement],p_envcrit)) -> 59472 | E63: =IF($B63="","",SUMIFS(TblApplications[Coût ROKS affecté (€)],TblApplications[Tribe],$B63,TblApplications[Environnement],p_envcrit)) -> 152111.1 | F63: =IF($B63="","",D63+E63) -> 211583.1 | I63: =IFERROR(IF(INDEX(TblDomaines[Domaine],1)="","",INDEX(TblDomaines[Domaine],1)),"") -> Distribution | J63: =IF($I63="","",SUMIFS(TblApplications[Coût IKS affecté (€)],TblApplications[Domaine],$I63,TblApplications[Environnement],p_envcrit)) -> 176292 | K63: =IF($I63="","",SUMIFS(TblApplications[Coût ROKS affecté (€)],TblApplications[Domaine],$I63,TblApplications[Environnement],p_envcrit)) -> 252802.38 | L63: =IF($I63="","",J63+K63) -> 429094.38
B64: =IFERROR(IF(INDEX(TblTribes[Tribe],2)="","",INDEX(TblTribes[Tribe],2)),"") -> Tarification | C64: =IF($B64="","",INDEX(TblTribes[Domaine de la tribe],2)) -> Distribution | D64: =IF($B64="","",SUMIFS(TblApplications[Coût IKS affecté (€)],TblApplications[Tribe],$B64,TblApplications[Environnement],p_envcrit)) -> 116820 | E64: =IF($B64="","",SUMIFS(TblApplications[Coût ROKS affecté (€)],TblApplications[Tribe],$B64,TblApplications[Environnement],p_envcrit)) -> 100691.28 | F64: =IF($B64="","",D64+E64) -> 217511.28 | I64: =IFERROR(IF(INDEX(TblDomaines[Domaine],2)="","",INDEX(TblDomaines[Domaine],2)),"") -> Indemnisation | J64: =IF($I64="","",SUMIFS(TblApplications[Coût IKS affecté (€)],TblApplications[Domaine],$I64,TblApplications[Environnement],p_envcrit)) -> 180540 | K64: =IF($I64="","",SUMIFS(TblApplications[Coût ROKS affecté (€)],TblApplications[Domaine],$I64,TblApplications[Environnement],p_envcrit)) -> 112427.91 | L64: =IF($I64="","",J64+K64) -> 292967.91
B65: =IFERROR(IF(INDEX(TblTribes[Tribe],3)="","",INDEX(TblTribes[Tribe],3)),"") -> Sinistres | C65: =IF($B65="","",INDEX(TblTribes[Domaine de la tribe],3)) -> Indemnisation | D65: =IF($B65="","",SUMIFS(TblApplications[Coût IKS affecté (€)],TblApplications[Tribe],$B65,TblApplications[Environnement],p_envcrit)) -> 180540 | E65: =IF($B65="","",SUMIFS(TblApplications[Coût ROKS affecté (€)],TblApplications[Tribe],$B65,TblApplications[Environnement],p_envcrit)) -> 112427.91 | F65: =IF($B65="","",D65+E65) -> 292967.91 | I65: =IFERROR(IF(INDEX(TblDomaines[Domaine],3)="","",INDEX(TblDomaines[Domaine],3)),"") | J65: =IF($I65="","",SUMIFS(TblApplications[Coût IKS affecté (€)],TblApplications[Domaine],$I65,TblApplications[Environnement],p_envcrit)) | K65: =IF($I65="","",SUMIFS(TblApplications[Coût ROKS affecté (€)],TblApplications[Domaine],$I65,TblApplications[Environnement],p_envcrit)) | L65: =IF($I65="","",J65+K65)
B66: =IFERROR(IF(INDEX(TblTribes[Tribe],4)="","",INDEX(TblTribes[Tribe],4)),"") | C66: =IF($B66="","",INDEX(TblTribes[Domaine de la tribe],4)) | D66: =IF($B66="","",SUMIFS(TblApplications[Coût IKS affecté (€)],TblApplications[Tribe],$B66,TblApplications[Environnement],p_envcrit)) | E66: =IF($B66="","",SUMIFS(TblApplications[Coût ROKS affecté (€)],TblApplications[Tribe],$B66,TblApplications[Environnement],p_envcrit)) | F66: =IF($B66="","",D66+E66) | I66: =IFERROR(IF(INDEX(TblDomaines[Domaine],4)="","",INDEX(TblDomaines[Domaine],4)),"") | J66: =IF($I66="","",SUMIFS(TblApplications[Coût IKS affecté (€)],TblApplications[Domaine],$I66,TblApplications[Environnement],p_envcrit)) | K66: =IF($I66="","",SUMIFS(TblApplications[Coût ROKS affecté (€)],TblApplications[Domaine],$I66,TblApplications[Environnement],p_envcrit)) | L66: =IF($I66="","",J66+K66)
B67: =IFERROR(IF(INDEX(TblTribes[Tribe],5)="","",INDEX(TblTribes[Tribe],5)),"") | C67: =IF($B67="","",INDEX(TblTribes[Domaine de la tribe],5)) | D67: =IF($B67="","",SUMIFS(TblApplications[Coût IKS affecté (€)],TblApplications[Tribe],$B67,TblApplications[Environnement],p_envcrit)) | E67: =IF($B67="","",SUMIFS(TblApplications[Coût ROKS affecté (€)],TblApplications[Tribe],$B67,TblApplications[Environnement],p_envcrit)) | F67: =IF($B67="","",D67+E67) | I67: =IFERROR(IF(INDEX(TblDomaines[Domaine],5)="","",INDEX(TblDomaines[Domaine],5)),"") | J67: =IF($I67="","",SUMIFS(TblApplications[Coût IKS affecté (€)],TblApplications[Domaine],$I67,TblApplications[Environnement],p_envcrit)) | K67: =IF($I67="","",SUMIFS(TblApplications[Coût ROKS affecté (€)],TblApplications[Domaine],$I67,TblApplications[Environnement],p_envcrit)) | L67: =IF($I67="","",J67+K67)
B68: =IFERROR(IF(INDEX(TblTribes[Tribe],6)="","",INDEX(TblTribes[Tribe],6)),"") | C68: =IF($B68="","",INDEX(TblTribes[Domaine de la tribe],6)) | D68: =IF($B68="","",SUMIFS(TblApplications[Coût IKS affecté (€)],TblApplications[Tribe],$B68,TblApplications[Environnement],p_envcrit)) | E68: =IF($B68="","",SUMIFS(TblApplications[Coût ROKS affecté (€)],TblApplications[Tribe],$B68,TblApplications[Environnement],p_envcrit)) | F68: =IF($B68="","",D68+E68) | I68: =IFERROR(IF(INDEX(TblDomaines[Domaine],6)="","",INDEX(TblDomaines[Domaine],6)),"") | J68: =IF($I68="","",SUMIFS(TblApplications[Coût IKS affecté (€)],TblApplications[Domaine],$I68,TblApplications[Environnement],p_envcrit)) | K68: =IF($I68="","",SUMIFS(TblApplications[Coût ROKS affecté (€)],TblApplications[Domaine],$I68,TblApplications[Environnement],p_envcrit)) | L68: =IF($I68="","",J68+K68)
B69: =IFERROR(IF(INDEX(TblTribes[Tribe],7)="","",INDEX(TblTribes[Tribe],7)),"") | C69: =IF($B69="","",INDEX(TblTribes[Domaine de la tribe],7)) | D69: =IF($B69="","",SUMIFS(TblApplications[Coût IKS affecté (€)],TblApplications[Tribe],$B69,TblApplications[Environnement],p_envcrit)) | E69: =IF($B69="","",SUMIFS(TblApplications[Coût ROKS affecté (€)],TblApplications[Tribe],$B69,TblApplications[Environnement],p_envcrit)) | F69: =IF($B69="","",D69+E69) | I69: =IFERROR(IF(INDEX(TblDomaines[Domaine],7)="","",INDEX(TblDomaines[Domaine],7)),"") | J69: =IF($I69="","",SUMIFS(TblApplications[Coût IKS affecté (€)],TblApplications[Domaine],$I69,TblApplications[Environnement],p_envcrit)) | K69: =IF($I69="","",SUMIFS(TblApplications[Coût ROKS affecté (€)],TblApplications[Domaine],$I69,TblApplications[Environnement],p_envcrit)) | L69: =IF($I69="","",J69+K69)
B70: =IFERROR(IF(INDEX(TblTribes[Tribe],8)="","",INDEX(TblTribes[Tribe],8)),"") | C70: =IF($B70="","",INDEX(TblTribes[Domaine de la tribe],8)) | D70: =IF($B70="","",SUMIFS(TblApplications[Coût IKS affecté (€)],TblApplications[Tribe],$B70,TblApplications[Environnement],p_envcrit)) | E70: =IF($B70="","",SUMIFS(TblApplications[Coût ROKS affecté (€)],TblApplications[Tribe],$B70,TblApplications[Environnement],p_envcrit)) | F70: =IF($B70="","",D70+E70) | I70: =IFERROR(IF(INDEX(TblDomaines[Domaine],8)="","",INDEX(TblDomaines[Domaine],8)),"") | J70: =IF($I70="","",SUMIFS(TblApplications[Coût IKS affecté (€)],TblApplications[Domaine],$I70,TblApplications[Environnement],p_envcrit)) | K70: =IF($I70="","",SUMIFS(TblApplications[Coût ROKS affecté (€)],TblApplications[Domaine],$I70,TblApplications[Environnement],p_envcrit)) | L70: =IF($I70="","",J70+K70)
B71: =IFERROR(IF(INDEX(TblTribes[Tribe],9)="","",INDEX(TblTribes[Tribe],9)),"") | C71: =IF($B71="","",INDEX(TblTribes[Domaine de la tribe],9)) | D71: =IF($B71="","",SUMIFS(TblApplications[Coût IKS affecté (€)],TblApplications[Tribe],$B71,TblApplications[Environnement],p_envcrit)) | E71: =IF($B71="","",SUMIFS(TblApplications[Coût ROKS affecté (€)],TblApplications[Tribe],$B71,TblApplications[Environnement],p_envcrit)) | F71: =IF($B71="","",D71+E71) | I71: =IFERROR(IF(INDEX(TblDomaines[Domaine],9)="","",INDEX(TblDomaines[Domaine],9)),"") | J71: =IF($I71="","",SUMIFS(TblApplications[Coût IKS affecté (€)],TblApplications[Domaine],$I71,TblApplications[Environnement],p_envcrit)) | K71: =IF($I71="","",SUMIFS(TblApplications[Coût ROKS affecté (€)],TblApplications[Domaine],$I71,TblApplications[Environnement],p_envcrit)) | L71: =IF($I71="","",J71+K71)
B72: =IFERROR(IF(INDEX(TblTribes[Tribe],10)="","",INDEX(TblTribes[Tribe],10)),"") | C72: =IF($B72="","",INDEX(TblTribes[Domaine de la tribe],10)) | D72: =IF($B72="","",SUMIFS(TblApplications[Coût IKS affecté (€)],TblApplications[Tribe],$B72,TblApplications[Environnement],p_envcrit)) | E72: =IF($B72="","",SUMIFS(TblApplications[Coût ROKS affecté (€)],TblApplications[Tribe],$B72,TblApplications[Environnement],p_envcrit)) | F72: =IF($B72="","",D72+E72) | I72: =IFERROR(IF(INDEX(TblDomaines[Domaine],10)="","",INDEX(TblDomaines[Domaine],10)),"") | J72: =IF($I72="","",SUMIFS(TblApplications[Coût IKS affecté (€)],TblApplications[Domaine],$I72,TblApplications[Environnement],p_envcrit)) | K72: =IF($I72="","",SUMIFS(TblApplications[Coût ROKS affecté (€)],TblApplications[Domaine],$I72,TblApplications[Environnement],p_envcrit)) | L72: =IF($I72="","",J72+K72)
B73: =IFERROR(IF(INDEX(TblTribes[Tribe],11)="","",INDEX(TblTribes[Tribe],11)),"") | C73: =IF($B73="","",INDEX(TblTribes[Domaine de la tribe],11)) | D73: =IF($B73="","",SUMIFS(TblApplications[Coût IKS affecté (€)],TblApplications[Tribe],$B73,TblApplications[Environnement],p_envcrit)) | E73: =IF($B73="","",SUMIFS(TblApplications[Coût ROKS affecté (€)],TblApplications[Tribe],$B73,TblApplications[Environnement],p_envcrit)) | F73: =IF($B73="","",D73+E73) | I73: =IFERROR(IF(INDEX(TblDomaines[Domaine],11)="","",INDEX(TblDomaines[Domaine],11)),"") | J73: =IF($I73="","",SUMIFS(TblApplications[Coût IKS affecté (€)],TblApplications[Domaine],$I73,TblApplications[Environnement],p_envcrit)) | K73: =IF($I73="","",SUMIFS(TblApplications[Coût ROKS affecté (€)],TblApplications[Domaine],$I73,TblApplications[Environnement],p_envcrit)) | L73: =IF($I73="","",J73+K73)
B74: =IFERROR(IF(INDEX(TblTribes[Tribe],12)="","",INDEX(TblTribes[Tribe],12)),"") | C74: =IF($B74="","",INDEX(TblTribes[Domaine de la tribe],12)) | D74: =IF($B74="","",SUMIFS(TblApplications[Coût IKS affecté (€)],TblApplications[Tribe],$B74,TblApplications[Environnement],p_envcrit)) | E74: =IF($B74="","",SUMIFS(TblApplications[Coût ROKS affecté (€)],TblApplications[Tribe],$B74,TblApplications[Environnement],p_envcrit)) | F74: =IF($B74="","",D74+E74) | I74: =IFERROR(IF(INDEX(TblDomaines[Domaine],12)="","",INDEX(TblDomaines[Domaine],12)),"") | J74: =IF($I74="","",SUMIFS(TblApplications[Coût IKS affecté (€)],TblApplications[Domaine],$I74,TblApplications[Environnement],p_envcrit)) | K74: =IF($I74="","",SUMIFS(TblApplications[Coût ROKS affecté (€)],TblApplications[Domaine],$I74,TblApplications[Environnement],p_envcrit)) | L74: =IF($I74="","",J74+K74)
B75: =IFERROR(IF(INDEX(TblTribes[Tribe],13)="","",INDEX(TblTribes[Tribe],13)),"") | C75: =IF($B75="","",INDEX(TblTribes[Domaine de la tribe],13)) | D75: =IF($B75="","",SUMIFS(TblApplications[Coût IKS affecté (€)],TblApplications[Tribe],$B75,TblApplications[Environnement],p_envcrit)) | E75: =IF($B75="","",SUMIFS(TblApplications[Coût ROKS affecté (€)],TblApplications[Tribe],$B75,TblApplications[Environnement],p_envcrit)) | F75: =IF($B75="","",D75+E75) | I75: =IFERROR(IF(INDEX(TblDomaines[Domaine],13)="","",INDEX(TblDomaines[Domaine],13)),"") | J75: =IF($I75="","",SUMIFS(TblApplications[Coût IKS affecté (€)],TblApplications[Domaine],$I75,TblApplications[Environnement],p_envcrit)) | K75: =IF($I75="","",SUMIFS(TblApplications[Coût ROKS affecté (€)],TblApplications[Domaine],$I75,TblApplications[Environnement],p_envcrit)) | L75: =IF($I75="","",J75+K75)
B76: =IFERROR(IF(INDEX(TblTribes[Tribe],14)="","",INDEX(TblTribes[Tribe],14)),"") | C76: =IF($B76="","",INDEX(TblTribes[Domaine de la tribe],14)) | D76: =IF($B76="","",SUMIFS(TblApplications[Coût IKS affecté (€)],TblApplications[Tribe],$B76,TblApplications[Environnement],p_envcrit)) | E76: =IF($B76="","",SUMIFS(TblApplications[Coût ROKS affecté (€)],TblApplications[Tribe],$B76,TblApplications[Environnement],p_envcrit)) | F76: =IF($B76="","",D76+E76) | I76: =IFERROR(IF(INDEX(TblDomaines[Domaine],14)="","",INDEX(TblDomaines[Domaine],14)),"") | J76: =IF($I76="","",SUMIFS(TblApplications[Coût IKS affecté (€)],TblApplications[Domaine],$I76,TblApplications[Environnement],p_envcrit)) | K76: =IF($I76="","",SUMIFS(TblApplications[Coût ROKS affecté (€)],TblApplications[Domaine],$I76,TblApplications[Environnement],p_envcrit)) | L76: =IF($I76="","",J76+K76)
B77: =IFERROR(IF(INDEX(TblTribes[Tribe],15)="","",INDEX(TblTribes[Tribe],15)),"") | C77: =IF($B77="","",INDEX(TblTribes[Domaine de la tribe],15)) | D77: =IF($B77="","",SUMIFS(TblApplications[Coût IKS affecté (€)],TblApplications[Tribe],$B77,TblApplications[Environnement],p_envcrit)) | E77: =IF($B77="","",SUMIFS(TblApplications[Coût ROKS affecté (€)],TblApplications[Tribe],$B77,TblApplications[Environnement],p_envcrit)) | F77: =IF($B77="","",D77+E77) | I77: =IFERROR(IF(INDEX(TblDomaines[Domaine],15)="","",INDEX(TblDomaines[Domaine],15)),"") | J77: =IF($I77="","",SUMIFS(TblApplications[Coût IKS affecté (€)],TblApplications[Domaine],$I77,TblApplications[Environnement],p_envcrit)) | K77: =IF($I77="","",SUMIFS(TblApplications[Coût ROKS affecté (€)],TblApplications[Domaine],$I77,TblApplications[Environnement],p_envcrit)) | L77: =IF($I77="","",J77+K77)
B78: =IFERROR(IF(INDEX(TblTribes[Tribe],16)="","",INDEX(TblTribes[Tribe],16)),"") | C78: =IF($B78="","",INDEX(TblTribes[Domaine de la tribe],16)) | D78: =IF($B78="","",SUMIFS(TblApplications[Coût IKS affecté (€)],TblApplications[Tribe],$B78,TblApplications[Environnement],p_envcrit)) | E78: =IF($B78="","",SUMIFS(TblApplications[Coût ROKS affecté (€)],TblApplications[Tribe],$B78,TblApplications[Environnement],p_envcrit)) | F78: =IF($B78="","",D78+E78) | I78: =IFERROR(IF(INDEX(TblDomaines[Domaine],16)="","",INDEX(TblDomaines[Domaine],16)),"") | J78: =IF($I78="","",SUMIFS(TblApplications[Coût IKS affecté (€)],TblApplications[Domaine],$I78,TblApplications[Environnement],p_envcrit)) | K78: =IF($I78="","",SUMIFS(TblApplications[Coût ROKS affecté (€)],TblApplications[Domaine],$I78,TblApplications[Environnement],p_envcrit)) | L78: =IF($I78="","",J78+K78)
B79: =IFERROR(IF(INDEX(TblTribes[Tribe],17)="","",INDEX(TblTribes[Tribe],17)),"") | C79: =IF($B79="","",INDEX(TblTribes[Domaine de la tribe],17)) | D79: =IF($B79="","",SUMIFS(TblApplications[Coût IKS affecté (€)],TblApplications[Tribe],$B79,TblApplications[Environnement],p_envcrit)) | E79: =IF($B79="","",SUMIFS(TblApplications[Coût ROKS affecté (€)],TblApplications[Tribe],$B79,TblApplications[Environnement],p_envcrit)) | F79: =IF($B79="","",D79+E79) | I79: =IFERROR(IF(INDEX(TblDomaines[Domaine],17)="","",INDEX(TblDomaines[Domaine],17)),"") | J79: =IF($I79="","",SUMIFS(TblApplications[Coût IKS affecté (€)],TblApplications[Domaine],$I79,TblApplications[Environnement],p_envcrit)) | K79: =IF($I79="","",SUMIFS(TblApplications[Coût ROKS affecté (€)],TblApplications[Domaine],$I79,TblApplications[Environnement],p_envcrit)) | L79: =IF($I79="","",J79+K79)
B80: =IFERROR(IF(INDEX(TblTribes[Tribe],18)="","",INDEX(TblTribes[Tribe],18)),"") | C80: =IF($B80="","",INDEX(TblTribes[Domaine de la tribe],18)) | D80: =IF($B80="","",SUMIFS(TblApplications[Coût IKS affecté (€)],TblApplications[Tribe],$B80,TblApplications[Environnement],p_envcrit)) | E80: =IF($B80="","",SUMIFS(TblApplications[Coût ROKS affecté (€)],TblApplications[Tribe],$B80,TblApplications[Environnement],p_envcrit)) | F80: =IF($B80="","",D80+E80) | I80: =IFERROR(IF(INDEX(TblDomaines[Domaine],18)="","",INDEX(TblDomaines[Domaine],18)),"") | J80: =IF($I80="","",SUMIFS(TblApplications[Coût IKS affecté (€)],TblApplications[Domaine],$I80,TblApplications[Environnement],p_envcrit)) | K80: =IF($I80="","",SUMIFS(TblApplications[Coût ROKS affecté (€)],TblApplications[Domaine],$I80,TblApplications[Environnement],p_envcrit)) | L80: =IF($I80="","",J80+K80)
B81: =IFERROR(IF(INDEX(TblTribes[Tribe],19)="","",INDEX(TblTribes[Tribe],19)),"") | C81: =IF($B81="","",INDEX(TblTribes[Domaine de la tribe],19)) | D81: =IF($B81="","",SUMIFS(TblApplications[Coût IKS affecté (€)],TblApplications[Tribe],$B81,TblApplications[Environnement],p_envcrit)) | E81: =IF($B81="","",SUMIFS(TblApplications[Coût ROKS affecté (€)],TblApplications[Tribe],$B81,TblApplications[Environnement],p_envcrit)) | F81: =IF($B81="","",D81+E81) | I81: =IFERROR(IF(INDEX(TblDomaines[Domaine],19)="","",INDEX(TblDomaines[Domaine],19)),"") | J81: =IF($I81="","",SUMIFS(TblApplications[Coût IKS affecté (€)],TblApplications[Domaine],$I81,TblApplications[Environnement],p_envcrit)) | K81: =IF($I81="","",SUMIFS(TblApplications[Coût ROKS affecté (€)],TblApplications[Domaine],$I81,TblApplications[Environnement],p_envcrit)) | L81: =IF($I81="","",J81+K81)
B82: =IFERROR(IF(INDEX(TblTribes[Tribe],20)="","",INDEX(TblTribes[Tribe],20)),"") | C82: =IF($B82="","",INDEX(TblTribes[Domaine de la tribe],20)) | D82: =IF($B82="","",SUMIFS(TblApplications[Coût IKS affecté (€)],TblApplications[Tribe],$B82,TblApplications[Environnement],p_envcrit)) | E82: =IF($B82="","",SUMIFS(TblApplications[Coût ROKS affecté (€)],TblApplications[Tribe],$B82,TblApplications[Environnement],p_envcrit)) | F82: =IF($B82="","",D82+E82) | I82: =IFERROR(IF(INDEX(TblDomaines[Domaine],20)="","",INDEX(TblDomaines[Domaine],20)),"") | J82: =IF($I82="","",SUMIFS(TblApplications[Coût IKS affecté (€)],TblApplications[Domaine],$I82,TblApplications[Environnement],p_envcrit)) | K82: =IF($I82="","",SUMIFS(TblApplications[Coût ROKS affecté (€)],TblApplications[Domaine],$I82,TblApplications[Environnement],p_envcrit)) | L82: =IF($I82="","",J82+K82)
B83: =IFERROR(IF(INDEX(TblTribes[Tribe],21)="","",INDEX(TblTribes[Tribe],21)),"") | C83: =IF($B83="","",INDEX(TblTribes[Domaine de la tribe],21)) | D83: =IF($B83="","",SUMIFS(TblApplications[Coût IKS affecté (€)],TblApplications[Tribe],$B83,TblApplications[Environnement],p_envcrit)) | E83: =IF($B83="","",SUMIFS(TblApplications[Coût ROKS affecté (€)],TblApplications[Tribe],$B83,TblApplications[Environnement],p_envcrit)) | F83: =IF($B83="","",D83+E83)
B84: =IFERROR(IF(INDEX(TblTribes[Tribe],22)="","",INDEX(TblTribes[Tribe],22)),"") | C84: =IF($B84="","",INDEX(TblTribes[Domaine de la tribe],22)) | D84: =IF($B84="","",SUMIFS(TblApplications[Coût IKS affecté (€)],TblApplications[Tribe],$B84,TblApplications[Environnement],p_envcrit)) | E84: =IF($B84="","",SUMIFS(TblApplications[Coût ROKS affecté (€)],TblApplications[Tribe],$B84,TblApplications[Environnement],p_envcrit)) | F84: =IF($B84="","",D84+E84)
B85: =IFERROR(IF(INDEX(TblTribes[Tribe],23)="","",INDEX(TblTribes[Tribe],23)),"") | C85: =IF($B85="","",INDEX(TblTribes[Domaine de la tribe],23)) | D85: =IF($B85="","",SUMIFS(TblApplications[Coût IKS affecté (€)],TblApplications[Tribe],$B85,TblApplications[Environnement],p_envcrit)) | E85: =IF($B85="","",SUMIFS(TblApplications[Coût ROKS affecté (€)],TblApplications[Tribe],$B85,TblApplications[Environnement],p_envcrit)) | F85: =IF($B85="","",D85+E85)
B86: =IFERROR(IF(INDEX(TblTribes[Tribe],24)="","",INDEX(TblTribes[Tribe],24)),"") | C86: =IF($B86="","",INDEX(TblTribes[Domaine de la tribe],24)) | D86: =IF($B86="","",SUMIFS(TblApplications[Coût IKS affecté (€)],TblApplications[Tribe],$B86,TblApplications[Environnement],p_envcrit)) | E86: =IF($B86="","",SUMIFS(TblApplications[Coût ROKS affecté (€)],TblApplications[Tribe],$B86,TblApplications[Environnement],p_envcrit)) | F86: =IF($B86="","",D86+E86)
B87: =IFERROR(IF(INDEX(TblTribes[Tribe],25)="","",INDEX(TblTribes[Tribe],25)),"") | C87: =IF($B87="","",INDEX(TblTribes[Domaine de la tribe],25)) | D87: =IF($B87="","",SUMIFS(TblApplications[Coût IKS affecté (€)],TblApplications[Tribe],$B87,TblApplications[Environnement],p_envcrit)) | E87: =IF($B87="","",SUMIFS(TblApplications[Coût ROKS affecté (€)],TblApplications[Tribe],$B87,TblApplications[Environnement],p_envcrit)) | F87: =IF($B87="","",D87+E87)
B88: =IFERROR(IF(INDEX(TblTribes[Tribe],26)="","",INDEX(TblTribes[Tribe],26)),"") | C88: =IF($B88="","",INDEX(TblTribes[Domaine de la tribe],26)) | D88: =IF($B88="","",SUMIFS(TblApplications[Coût IKS affecté (€)],TblApplications[Tribe],$B88,TblApplications[Environnement],p_envcrit)) | E88: =IF($B88="","",SUMIFS(TblApplications[Coût ROKS affecté (€)],TblApplications[Tribe],$B88,TblApplications[Environnement],p_envcrit)) | F88: =IF($B88="","",D88+E88)
B89: =IFERROR(IF(INDEX(TblTribes[Tribe],27)="","",INDEX(TblTribes[Tribe],27)),"") | C89: =IF($B89="","",INDEX(TblTribes[Domaine de la tribe],27)) | D89: =IF($B89="","",SUMIFS(TblApplications[Coût IKS affecté (€)],TblApplications[Tribe],$B89,TblApplications[Environnement],p_envcrit)) | E89: =IF($B89="","",SUMIFS(TblApplications[Coût ROKS affecté (€)],TblApplications[Tribe],$B89,TblApplications[Environnement],p_envcrit)) | F89: =IF($B89="","",D89+E89)
...

Sheet Avancement
B1: Avancement de la migration
B2: Déploiements par action, par tribe, domaine et environnement ; frise des migrations prévues. Filtres ligne 4.
B4: Environnement | C4: Tous | E4: Domaine | F4: Tous | H4: Tribe | I4: Tous | K4: Mois de référence | L4: 46722 | AD4: =IF(C4="Tous","*",C4) -> * | AE4: =IF(F4="Tous","*",F4) -> * | AF4: =IF(I4="Tous","*",I4) -> * | AG4: =IFERROR(DATE(YEAR(L4),MONTH(L4),1),p_debut) -> 46722
B6: Migrés | D6: À migrer | F6: À décommissionner | H6: Décommissionnés | J6: Traités au mois de référence | L6: % traité au mois de référence
B7: =COUNTIFS(TblApplications[Action],"Migré",TblApplications[Environnement],av_envc,TblApplications[Domaine],av_domc,TblApplications[Tribe],av_tric) -> 1 | D7: =COUNTIFS(TblApplications[Action],"À migrer",TblApplications[Environnement],av_envc,TblApplications[Domaine],av_domc,TblApplications[Tribe],av_tric) -> 10 | F7: =COUNTIFS(TblApplications[Action],"À décommissionner",TblApplications[Environnement],av_envc,TblApplications[Domaine],av_domc,TblApplications[Tribe],av_tric) -> 1 | H7: =COUNTIFS(TblApplications[Action],"Décommissionné",TblApplications[Environnement],av_envc,TblApplications[Domaine],av_domc,TblApplications[Tribe],av_tric) -> 1 | J7: =(COUNTIFS(TblApplications[Action],"Migré",TblApplications[Environnement],av_envc,TblApplications[Domaine],av_domc,TblApplications[Tribe],av_tric)+COUNTIFS(TblApplications[Action],"Décommissionné",TblApplications[Environnement],av_envc,TblApplications[Domaine],av_domc,TblApplications[Tribe],av_tric)+COUNTIFS(TblApplications[Action],"À migrer",TblApplications[Mois lib (calc)],"<="&av_mois,TblApplications[Environnement],av_envc,TblApplications[Domaine],av_domc,TblApplications[Tribe],av_tric)+COUNTIFS(TblApplications[Action],"À décommissionner",TblApplications[Mois lib (calc)],"<="&av_mois,TblApplications[Environnement],av_envc,TblApplications[Domaine],av_domc,TblApplications[Tribe],av_tric)) -> 9 | L7: =IFERROR((COUNTIFS(TblApplications[Action],"Migré",TblApplications[Environnement],av_envc,TblApplications[Domaine],av_domc,TblApplications[Tribe],av_tric)+COUNTIFS(TblApplications[Action],"Décommissionné",TblApplications[Environnement],av_envc,TblApplications[Domaine],av_domc,TblApplications[Tribe],av_tric)+COUNTIFS(TblApplications[Action],"À migrer",TblApplications[Mois lib (calc)],"<="&av_mois,TblApplications[Environnement],av_envc,TblApplications[Domaine],av_domc,TblApplications[Tribe],av_tric)+COUNTIFS(TblApplications[Action],"À décommissionner",TblApplications[Mois lib (calc)],"<="&av_mois,TblApplications[Environnement],av_envc,TblApplications[Domaine],av_domc,TblApplications[Tribe],av_tric))/COUNTIFS(TblApplications[ID],"<>",TblApplications[Environnement],av_envc,TblApplications[Domaine],av_domc,TblApplications[Tribe],av_tric),0) -> 0.69230769
B9: Traité = Migré ou Décommissionné, plus les déploiements « À migrer » / « À décommissionner » dont l'IKS est libéré au mois de référence.
B11: Répartition par tribe et par domaine (nombre de déploiements)
B33: Tribe | C33: Domaine | D33: Migré | E33: À migrer | F33: À décommissionner | G33: Décommissionné | H33: Total | K33: Domaine | L33: Migré | M33: À migrer | N33: À décommissionner | O33: Décommissionné | P33: Total
B34: =IFERROR(IF(INDEX(TblTribes[Tribe],1)="","",INDEX(TblTribes[Tribe],1)),"") -> Parcours client | C34: =IF($B34="","",INDEX(TblTribes[Domaine de la tribe],1)) -> Distribution | D34: =IF($B34="","",COUNTIFS(TblApplications[Tribe],$B34,TblApplications[Action],"Migré",TblApplications[Environnement],av_envc,TblApplications[Domaine],av_domc,TblApplications[Tribe],av_tric)) -> 0 | E34: =IF($B34="","",COUNTIFS(TblApplications[Tribe],$B34,TblApplications[Action],"À migrer",TblApplications[Environnement],av_envc,TblApplications[Domaine],av_domc,TblApplications[Tribe],av_tric)) -> 3 | F34: =IF($B34="","",COUNTIFS(TblApplications[Tribe],$B34,TblApplications[Action],"À décommissionner",TblApplications[Environnement],av_envc,TblApplications[Domaine],av_domc,TblApplications[Tribe],av_tric)) -> 1 | G34: =IF($B34="","",COUNTIFS(TblApplications[Tribe],$B34,TblApplications[Action],"Décommissionné",TblApplications[Environnement],av_envc,TblApplications[Domaine],av_domc,TblApplications[Tribe],av_tric)) -> 0 | H34: =IF($B34="","",SUM(D34:G34)) -> 4 | K34: =IFERROR(IF(INDEX(TblDomaines[Domaine],1)="","",INDEX(TblDomaines[Domaine],1)),"") -> Distribution | L34: =IF($K34="","",COUNTIFS(TblApplications[Domaine],$K34,TblApplications[Action],"Migré",TblApplications[Environnement],av_envc,TblApplications[Domaine],av_domc,TblApplications[Tribe],av_tric)) -> 0 | M34: =IF($K34="","",COUNTIFS(TblApplications[Domaine],$K34,TblApplications[Action],"À migrer",TblApplications[Environnement],av_envc,TblApplications[Domaine],av_domc,TblApplications[Tribe],av_tric)) -> 7 | N34: =IF($K34="","",COUNTIFS(TblApplications[Domaine],$K34,TblApplications[Action],"À décommissionner",TblApplications[Environnement],av_envc,TblApplications[Domaine],av_domc,TblApplications[Tribe],av_tric)) -> 1 | O34: =IF($K34="","",COUNTIFS(TblApplications[Domaine],$K34,TblApplications[Action],"Décommissionné",TblApplications[Environnement],av_envc,TblApplications[Domaine],av_domc,TblApplications[Tribe],av_tric)) -> 1 | P34: =IF($K34="","",SUM(L34:O34)) -> 9
B35: =IFERROR(IF(INDEX(TblTribes[Tribe],2)="","",INDEX(TblTribes[Tribe],2)),"") -> Tarification | C35: =IF($B35="","",INDEX(TblTribes[Domaine de la tribe],2)) -> Distribution | D35: =IF($B35="","",COUNTIFS(TblApplications[Tribe],$B35,TblApplications[Action],"Migré",TblApplications[Environnement],av_envc,TblApplications[Domaine],av_domc,TblApplications[Tribe],av_tric)) -> 0 | E35: =IF($B35="","",COUNTIFS(TblApplications[Tribe],$B35,TblApplications[Action],"À migrer",TblApplications[Environnement],av_envc,TblApplications[Domaine],av_domc,TblApplications[Tribe],av_tric)) -> 4 | F35: =IF($B35="","",COUNTIFS(TblApplications[Tribe],$B35,TblApplications[Action],"À décommissionner",TblApplications[Environnement],av_envc,TblApplications[Domaine],av_domc,TblApplications[Tribe],av_tric)) -> 0 | G35: =IF($B35="","",COUNTIFS(TblApplications[Tribe],$B35,TblApplications[Action],"Décommissionné",TblApplications[Environnement],av_envc,TblApplications[Domaine],av_domc,TblApplications[Tribe],av_tric)) -> 1 | H35: =IF($B35="","",SUM(D35:G35)) -> 5 | K35: =IFERROR(IF(INDEX(TblDomaines[Domaine],2)="","",INDEX(TblDomaines[Domaine],2)),"") -> Indemnisation | L35: =IF($K35="","",COUNTIFS(TblApplications[Domaine],$K35,TblApplications[Action],"Migré",TblApplications[Environnement],av_envc,TblApplications[Domaine],av_domc,TblApplications[Tribe],av_tric)) -> 1 | M35: =IF($K35="","",COUNTIFS(TblApplications[Domaine],$K35,TblApplications[Action],"À migrer",TblApplications[Environnement],av_envc,TblApplications[Domaine],av_domc,TblApplications[Tribe],av_tric)) -> 3 | N35: =IF($K35="","",COUNTIFS(TblApplications[Domaine],$K35,TblApplications[Action],"À décommissionner",TblApplications[Environnement],av_envc,TblApplications[Domaine],av_domc,TblApplications[Tribe],av_tric)) -> 0 | O35: =IF($K35="","",COUNTIFS(TblApplications[Domaine],$K35,TblApplications[Action],"Décommissionné",TblApplications[Environnement],av_envc,TblApplications[Domaine],av_domc,TblApplications[Tribe],av_tric)) -> 0 | P35: =IF($K35="","",SUM(L35:O35)) -> 4
B36: =IFERROR(IF(INDEX(TblTribes[Tribe],3)="","",INDEX(TblTribes[Tribe],3)),"") -> Sinistres | C36: =IF($B36="","",INDEX(TblTribes[Domaine de la tribe],3)) -> Indemnisation | D36: =IF($B36="","",COUNTIFS(TblApplications[Tribe],$B36,TblApplications[Action],"Migré",TblApplications[Environnement],av_envc,TblApplications[Domaine],av_domc,TblApplications[Tribe],av_tric)) -> 1 | E36: =IF($B36="","",COUNTIFS(TblApplications[Tribe],$B36,TblApplications[Action],"À migrer",TblApplications[Environnement],av_envc,TblApplications[Domaine],av_domc,TblApplications[Tribe],av_tric)) -> 3 | F36: =IF($B36="","",COUNTIFS(TblApplications[Tribe],$B36,TblApplications[Action],"À décommissionner",TblApplications[Environnement],av_envc,TblApplications[Domaine],av_domc,TblApplications[Tribe],av_tric)) -> 0 | G36: =IF($B36="","",COUNTIFS(TblApplications[Tribe],$B36,TblApplications[Action],"Décommissionné",TblApplications[Environnement],av_envc,TblApplications[Domaine],av_domc,TblApplications[Tribe],av_tric)) -> 0 | H36: =IF($B36="","",SUM(D36:G36)) -> 4 | K36: =IFERROR(IF(INDEX(TblDomaines[Domaine],3)="","",INDEX(TblDomaines[Domaine],3)),"") | L36: =IF($K36="","",COUNTIFS(TblApplications[Domaine],$K36,TblApplications[Action],"Migré",TblApplications[Environnement],av_envc,TblApplications[Domaine],av_domc,TblApplications[Tribe],av_tric)) | M36: =IF($K36="","",COUNTIFS(TblApplications[Domaine],$K36,TblApplications[Action],"À migrer",TblApplications[Environnement],av_envc,TblApplications[Domaine],av_domc,TblApplications[Tribe],av_tric)) | N36: =IF($K36="","",COUNTIFS(TblApplications[Domaine],$K36,TblApplications[Action],"À décommissionner",TblApplications[Environnement],av_envc,TblApplications[Domaine],av_domc,TblApplications[Tribe],av_tric)) | O36: =IF($K36="","",COUNTIFS(TblApplications[Domaine],$K36,TblApplications[Action],"Décommissionné",TblApplications[Environnement],av_envc,TblApplications[Domaine],av_domc,TblApplications[Tribe],av_tric)) | P36: =IF($K36="","",SUM(L36:O36))
B37: =IFERROR(IF(INDEX(TblTribes[Tribe],4)="","",INDEX(TblTribes[Tribe],4)),"") | C37: =IF($B37="","",INDEX(TblTribes[Domaine de la tribe],4)) | D37: =IF($B37="","",COUNTIFS(TblApplications[Tribe],$B37,TblApplications[Action],"Migré",TblApplications[Environnement],av_envc,TblApplications[Domaine],av_domc,TblApplications[Tribe],av_tric)) | E37: =IF($B37="","",COUNTIFS(TblApplications[Tribe],$B37,TblApplications[Action],"À migrer",TblApplications[Environnement],av_envc,TblApplications[Domaine],av_domc,TblApplications[Tribe],av_tric)) | F37: =IF($B37="","",COUNTIFS(TblApplications[Tribe],$B37,TblApplications[Action],"À décommissionner",TblApplications[Environnement],av_envc,TblApplications[Domaine],av_domc,TblApplications[Tribe],av_tric)) | G37: =IF($B37="","",COUNTIFS(TblApplications[Tribe],$B37,TblApplications[Action],"Décommissionné",TblApplications[Environnement],av_envc,TblApplications[Domaine],av_domc,TblApplications[Tribe],av_tric)) | H37: =IF($B37="","",SUM(D37:G37)) | K37: =IFERROR(IF(INDEX(TblDomaines[Domaine],4)="","",INDEX(TblDomaines[Domaine],4)),"") | L37: =IF($K37="","",COUNTIFS(TblApplications[Domaine],$K37,TblApplications[Action],"Migré",TblApplications[Environnement],av_envc,TblApplications[Domaine],av_domc,TblApplications[Tribe],av_tric)) | M37: =IF($K37="","",COUNTIFS(TblApplications[Domaine],$K37,TblApplications[Action],"À migrer",TblApplications[Environnement],av_envc,TblApplications[Domaine],av_domc,TblApplications[Tribe],av_tric)) | N37: =IF($K37="","",COUNTIFS(TblApplications[Domaine],$K37,TblApplications[Action],"À décommissionner",TblApplications[Environnement],av_envc,TblApplications[Domaine],av_domc,TblApplications[Tribe],av_tric)) | O37: =IF($K37="","",COUNTIFS(TblApplications[Domaine],$K37,TblApplications[Action],"Décommissionné",TblApplications[Environnement],av_envc,TblApplications[Domaine],av_domc,TblApplications[Tribe],av_tric)) | P37: =IF($K37="","",SUM(L37:O37))
B38: =IFERROR(IF(INDEX(TblTribes[Tribe],5)="","",INDEX(TblTribes[Tribe],5)),"") | C38: =IF($B38="","",INDEX(TblTribes[Domaine de la tribe],5)) | D38: =IF($B38="","",COUNTIFS(TblApplications[Tribe],$B38,TblApplications[Action],"Migré",TblApplications[Environnement],av_envc,TblApplications[Domaine],av_domc,TblApplications[Tribe],av_tric)) | E38: =IF($B38="","",COUNTIFS(TblApplications[Tribe],$B38,TblApplications[Action],"À migrer",TblApplications[Environnement],av_envc,TblApplications[Domaine],av_domc,TblApplications[Tribe],av_tric)) | F38: =IF($B38="","",COUNTIFS(TblApplications[Tribe],$B38,TblApplications[Action],"À décommissionner",TblApplications[Environnement],av_envc,TblApplications[Domaine],av_domc,TblApplications[Tribe],av_tric)) | G38: =IF($B38="","",COUNTIFS(TblApplications[Tribe],$B38,TblApplications[Action],"Décommissionné",TblApplications[Environnement],av_envc,TblApplications[Domaine],av_domc,TblApplications[Tribe],av_tric)) | H38: =IF($B38="","",SUM(D38:G38)) | K38: =IFERROR(IF(INDEX(TblDomaines[Domaine],5)="","",INDEX(TblDomaines[Domaine],5)),"") | L38: =IF($K38="","",COUNTIFS(TblApplications[Domaine],$K38,TblApplications[Action],"Migré",TblApplications[Environnement],av_envc,TblApplications[Domaine],av_domc,TblApplications[Tribe],av_tric)) | M38: =IF($K38="","",COUNTIFS(TblApplications[Domaine],$K38,TblApplications[Action],"À migrer",TblApplications[Environnement],av_envc,TblApplications[Domaine],av_domc,TblApplications[Tribe],av_tric)) | N38: =IF($K38="","",COUNTIFS(TblApplications[Domaine],$K38,TblApplications[Action],"À décommissionner",TblApplications[Environnement],av_envc,TblApplications[Domaine],av_domc,TblApplications[Tribe],av_tric)) | O38: =IF($K38="","",COUNTIFS(TblApplications[Domaine],$K38,TblApplications[Action],"Décommissionné",TblApplications[Environnement],av_envc,TblApplications[Domaine],av_domc,TblApplications[Tribe],av_tric)) | P38: =IF($K38="","",SUM(L38:O38))
B39: =IFERROR(IF(INDEX(TblTribes[Tribe],6)="","",INDEX(TblTribes[Tribe],6)),"") | C39: =IF($B39="","",INDEX(TblTribes[Domaine de la tribe],6)) | D39: =IF($B39="","",COUNTIFS(TblApplications[Tribe],$B39,TblApplications[Action],"Migré",TblApplications[Environnement],av_envc,TblApplications[Domaine],av_domc,TblApplications[Tribe],av_tric)) | E39: =IF($B39="","",COUNTIFS(TblApplications[Tribe],$B39,TblApplications[Action],"À migrer",TblApplications[Environnement],av_envc,TblApplications[Domaine],av_domc,TblApplications[Tribe],av_tric)) | F39: =IF($B39="","",COUNTIFS(TblApplications[Tribe],$B39,TblApplications[Action],"À décommissionner",TblApplications[Environnement],av_envc,TblApplications[Domaine],av_domc,TblApplications[Tribe],av_tric)) | G39: =IF($B39="","",COUNTIFS(TblApplications[Tribe],$B39,TblApplications[Action],"Décommissionné",TblApplications[Environnement],av_envc,TblApplications[Domaine],av_domc,TblApplications[Tribe],av_tric)) | H39: =IF($B39="","",SUM(D39:G39)) | K39: =IFERROR(IF(INDEX(TblDomaines[Domaine],6)="","",INDEX(TblDomaines[Domaine],6)),"") | L39: =IF($K39="","",COUNTIFS(TblApplications[Domaine],$K39,TblApplications[Action],"Migré",TblApplications[Environnement],av_envc,TblApplications[Domaine],av_domc,TblApplications[Tribe],av_tric)) | M39: =IF($K39="","",COUNTIFS(TblApplications[Domaine],$K39,TblApplications[Action],"À migrer",TblApplications[Environnement],av_envc,TblApplications[Domaine],av_domc,TblApplications[Tribe],av_tric)) | N39: =IF($K39="","",COUNTIFS(TblApplications[Domaine],$K39,TblApplications[Action],"À décommissionner",TblApplications[Environnement],av_envc,TblApplications[Domaine],av_domc,TblApplications[Tribe],av_tric)) | O39: =IF($K39="","",COUNTIFS(TblApplications[Domaine],$K39,TblApplications[Action],"Décommissionné",TblApplications[Environnement],av_envc,TblApplications[Domaine],av_domc,TblApplications[Tribe],av_tric)) | P39: =IF($K39="","",SUM(L39:O39))
B40: =IFERROR(IF(INDEX(TblTribes[Tribe],7)="","",INDEX(TblTribes[Tribe],7)),"") | C40: =IF($B40="","",INDEX(TblTribes[Domaine de la tribe],7)) | D40: =IF($B40="","",COUNTIFS(TblApplications[Tribe],$B40,TblApplications[Action],"Migré",TblApplications[Environnement],av_envc,TblApplications[Domaine],av_domc,TblApplications[Tribe],av_tric)) | E40: =IF($B40="","",COUNTIFS(TblApplications[Tribe],$B40,TblApplications[Action],"À migrer",TblApplications[Environnement],av_envc,TblApplications[Domaine],av_domc,TblApplications[Tribe],av_tric)) | F40: =IF($B40="","",COUNTIFS(TblApplications[Tribe],$B40,TblApplications[Action],"À décommissionner",TblApplications[Environnement],av_envc,TblApplications[Domaine],av_domc,TblApplications[Tribe],av_tric)) | G40: =IF($B40="","",COUNTIFS(TblApplications[Tribe],$B40,TblApplications[Action],"Décommissionné",TblApplications[Environnement],av_envc,TblApplications[Domaine],av_domc,TblApplications[Tribe],av_tric)) | H40: =IF($B40="","",SUM(D40:G40)) | K40: =IFERROR(IF(INDEX(TblDomaines[Domaine],7)="","",INDEX(TblDomaines[Domaine],7)),"") | L40: =IF($K40="","",COUNTIFS(TblApplications[Domaine],$K40,TblApplications[Action],"Migré",TblApplications[Environnement],av_envc,TblApplications[Domaine],av_domc,TblApplications[Tribe],av_tric)) | M40: =IF($K40="","",COUNTIFS(TblApplications[Domaine],$K40,TblApplications[Action],"À migrer",TblApplications[Environnement],av_envc,TblApplications[Domaine],av_domc,TblApplications[Tribe],av_tric)) | N40: =IF($K40="","",COUNTIFS(TblApplications[Domaine],$K40,TblApplications[Action],"À décommissionner",TblApplications[Environnement],av_envc,TblApplications[Domaine],av_domc,TblApplications[Tribe],av_tric)) | O40: =IF($K40="","",COUNTIFS(TblApplications[Domaine],$K40,TblApplications[Action],"Décommissionné",TblApplications[Environnement],av_envc,TblApplications[Domaine],av_domc,TblApplications[Tribe],av_tric)) | P40: =IF($K40="","",SUM(L40:O40))
B41: =IFERROR(IF(INDEX(TblTribes[Tribe],8)="","",INDEX(TblTribes[Tribe],8)),"") | C41: =IF($B41="","",INDEX(TblTribes[Domaine de la tribe],8)) | D41: =IF($B41="","",COUNTIFS(TblApplications[Tribe],$B41,TblApplications[Action],"Migré",TblApplications[Environnement],av_envc,TblApplications[Domaine],av_domc,TblApplications[Tribe],av_tric)) | E41: =IF($B41="","",COUNTIFS(TblApplications[Tribe],$B41,TblApplications[Action],"À migrer",TblApplications[Environnement],av_envc,TblApplications[Domaine],av_domc,TblApplications[Tribe],av_tric)) | F41: =IF($B41="","",COUNTIFS(TblApplications[Tribe],$B41,TblApplications[Action],"À décommissionner",TblApplications[Environnement],av_envc,TblApplications[Domaine],av_domc,TblApplications[Tribe],av_tric)) | G41: =IF($B41="","",COUNTIFS(TblApplications[Tribe],$B41,TblApplications[Action],"Décommissionné",TblApplications[Environnement],av_envc,TblApplications[Domaine],av_domc,TblApplications[Tribe],av_tric)) | H41: =IF($B41="","",SUM(D41:G41)) | K41: =IFERROR(IF(INDEX(TblDomaines[Domaine],8)="","",INDEX(TblDomaines[Domaine],8)),"") | L41: =IF($K41="","",COUNTIFS(TblApplications[Domaine],$K41,TblApplications[Action],"Migré",TblApplications[Environnement],av_envc,TblApplications[Domaine],av_domc,TblApplications[Tribe],av_tric)) | M41: =IF($K41="","",COUNTIFS(TblApplications[Domaine],$K41,TblApplications[Action],"À migrer",TblApplications[Environnement],av_envc,TblApplications[Domaine],av_domc,TblApplications[Tribe],av_tric)) | N41: =IF($K41="","",COUNTIFS(TblApplications[Domaine],$K41,TblApplications[Action],"À décommissionner",TblApplications[Environnement],av_envc,TblApplications[Domaine],av_domc,TblApplications[Tribe],av_tric)) | O41: =IF($K41="","",COUNTIFS(TblApplications[Domaine],$K41,TblApplications[Action],"Décommissionné",TblApplications[Environnement],av_envc,TblApplications[Domaine],av_domc,TblApplications[Tribe],av_tric)) | P41: =IF($K41="","",SUM(L41:O41))
B42: =IFERROR(IF(INDEX(TblTribes[Tribe],9)="","",INDEX(TblTribes[Tribe],9)),"") | C42: =IF($B42="","",INDEX(TblTribes[Domaine de la tribe],9)) | D42: =IF($B42="","",COUNTIFS(TblApplications[Tribe],$B42,TblApplications[Action],"Migré",TblApplications[Environnement],av_envc,TblApplications[Domaine],av_domc,TblApplications[Tribe],av_tric)) | E42: =IF($B42="","",COUNTIFS(TblApplications[Tribe],$B42,TblApplications[Action],"À migrer",TblApplications[Environnement],av_envc,TblApplications[Domaine],av_domc,TblApplications[Tribe],av_tric)) | F42: =IF($B42="","",COUNTIFS(TblApplications[Tribe],$B42,TblApplications[Action],"À décommissionner",TblApplications[Environnement],av_envc,TblApplications[Domaine],av_domc,TblApplications[Tribe],av_tric)) | G42: =IF($B42="","",COUNTIFS(TblApplications[Tribe],$B42,TblApplications[Action],"Décommissionné",TblApplications[Environnement],av_envc,TblApplications[Domaine],av_domc,TblApplications[Tribe],av_tric)) | H42: =IF($B42="","",SUM(D42:G42)) | K42: =IFERROR(IF(INDEX(TblDomaines[Domaine],9)="","",INDEX(TblDomaines[Domaine],9)),"") | L42: =IF($K42="","",COUNTIFS(TblApplications[Domaine],$K42,TblApplications[Action],"Migré",TblApplications[Environnement],av_envc,TblApplications[Domaine],av_domc,TblApplications[Tribe],av_tric)) | M42: =IF($K42="","",COUNTIFS(TblApplications[Domaine],$K42,TblApplications[Action],"À migrer",TblApplications[Environnement],av_envc,TblApplications[Domaine],av_domc,TblApplications[Tribe],av_tric)) | N42: =IF($K42="","",COUNTIFS(TblApplications[Domaine],$K42,TblApplications[Action],"À décommissionner",TblApplications[Environnement],av_envc,TblApplications[Domaine],av_domc,TblApplications[Tribe],av_tric)) | O42: =IF($K42="","",COUNTIFS(TblApplications[Domaine],$K42,TblApplications[Action],"Décommissionné",TblApplications[Environnement],av_envc,TblApplications[Domaine],av_domc,TblApplications[Tribe],av_tric)) | P42: =IF($K42="","",SUM(L42:O42))
B43: =IFERROR(IF(INDEX(TblTribes[Tribe],10)="","",INDEX(TblTribes[Tribe],10)),"") | C43: =IF($B43="","",INDEX(TblTribes[Domaine de la tribe],10)) | D43: =IF($B43="","",COUNTIFS(TblApplications[Tribe],$B43,TblApplications[Action],"Migré",TblApplications[Environnement],av_envc,TblApplications[Domaine],av_domc,TblApplications[Tribe],av_tric)) | E43: =IF($B43="","",COUNTIFS(TblApplications[Tribe],$B43,TblApplications[Action],"À migrer",TblApplications[Environnement],av_envc,TblApplications[Domaine],av_domc,TblApplications[Tribe],av_tric)) | F43: =IF($B43="","",COUNTIFS(TblApplications[Tribe],$B43,TblApplications[Action],"À décommissionner",TblApplications[Environnement],av_envc,TblApplications[Domaine],av_domc,TblApplications[Tribe],av_tric)) | G43: =IF($B43="","",COUNTIFS(TblApplications[Tribe],$B43,TblApplications[Action],"Décommissionné",TblApplications[Environnement],av_envc,TblApplications[Domaine],av_domc,TblApplications[Tribe],av_tric)) | H43: =IF($B43="","",SUM(D43:G43)) | K43: =IFERROR(IF(INDEX(TblDomaines[Domaine],10)="","",INDEX(TblDomaines[Domaine],10)),"") | L43: =IF($K43="","",COUNTIFS(TblApplications[Domaine],$K43,TblApplications[Action],"Migré",TblApplications[Environnement],av_envc,TblApplications[Domaine],av_domc,TblApplications[Tribe],av_tric)) | M43: =IF($K43="","",COUNTIFS(TblApplications[Domaine],$K43,TblApplications[Action],"À migrer",TblApplications[Environnement],av_envc,TblApplications[Domaine],av_domc,TblApplications[Tribe],av_tric)) | N43: =IF($K43="","",COUNTIFS(TblApplications[Domaine],$K43,TblApplications[Action],"À décommissionner",TblApplications[Environnement],av_envc,TblApplications[Domaine],av_domc,TblApplications[Tribe],av_tric)) | O43: =IF($K43="","",COUNTIFS(TblApplications[Domaine],$K43,TblApplications[Action],"Décommissionné",TblApplications[Environnement],av_envc,TblApplications[Domaine],av_domc,TblApplications[Tribe],av_tric)) | P43: =IF($K43="","",SUM(L43:O43))
B44: =IFERROR(IF(INDEX(TblTribes[Tribe],11)="","",INDEX(TblTribes[Tribe],11)),"") | C44: =IF($B44="","",INDEX(TblTribes[Domaine de la tribe],11)) | D44: =IF($B44="","",COUNTIFS(TblApplications[Tribe],$B44,TblApplications[Action],"Migré",TblApplications[Environnement],av_envc,TblApplications[Domaine],av_domc,TblApplications[Tribe],av_tric)) | E44: =IF($B44="","",COUNTIFS(TblApplications[Tribe],$B44,TblApplications[Action],"À migrer",TblApplications[Environnement],av_envc,TblApplications[Domaine],av_domc,TblApplications[Tribe],av_tric)) | F44: =IF($B44="","",COUNTIFS(TblApplications[Tribe],$B44,TblApplications[Action],"À décommissionner",TblApplications[Environnement],av_envc,TblApplications[Domaine],av_domc,TblApplications[Tribe],av_tric)) | G44: =IF($B44="","",COUNTIFS(TblApplications[Tribe],$B44,TblApplications[Action],"Décommissionné",TblApplications[Environnement],av_envc,TblApplications[Domaine],av_domc,TblApplications[Tribe],av_tric)) | H44: =IF($B44="","",SUM(D44:G44)) | K44: =IFERROR(IF(INDEX(TblDomaines[Domaine],11)="","",INDEX(TblDomaines[Domaine],11)),"") | L44: =IF($K44="","",COUNTIFS(TblApplications[Domaine],$K44,TblApplications[Action],"Migré",TblApplications[Environnement],av_envc,TblApplications[Domaine],av_domc,TblApplications[Tribe],av_tric)) | M44: =IF($K44="","",COUNTIFS(TblApplications[Domaine],$K44,TblApplications[Action],"À migrer",TblApplications[Environnement],av_envc,TblApplications[Domaine],av_domc,TblApplications[Tribe],av_tric)) | N44: =IF($K44="","",COUNTIFS(TblApplications[Domaine],$K44,TblApplications[Action],"À décommissionner",TblApplications[Environnement],av_envc,TblApplications[Domaine],av_domc,TblApplications[Tribe],av_tric)) | O44: =IF($K44="","",COUNTIFS(TblApplications[Domaine],$K44,TblApplications[Action],"Décommissionné",TblApplications[Environnement],av_envc,TblApplications[Domaine],av_domc,TblApplications[Tribe],av_tric)) | P44: =IF($K44="","",SUM(L44:O44))
B45: =IFERROR(IF(INDEX(TblTribes[Tribe],12)="","",INDEX(TblTribes[Tribe],12)),"") | C45: =IF($B45="","",INDEX(TblTribes[Domaine de la tribe],12)) | D45: =IF($B45="","",COUNTIFS(TblApplications[Tribe],$B45,TblApplications[Action],"Migré",TblApplications[Environnement],av_envc,TblApplications[Domaine],av_domc,TblApplications[Tribe],av_tric)) | E45: =IF($B45="","",COUNTIFS(TblApplications[Tribe],$B45,TblApplications[Action],"À migrer",TblApplications[Environnement],av_envc,TblApplications[Domaine],av_domc,TblApplications[Tribe],av_tric)) | F45: =IF($B45="","",COUNTIFS(TblApplications[Tribe],$B45,TblApplications[Action],"À décommissionner",TblApplications[Environnement],av_envc,TblApplications[Domaine],av_domc,TblApplications[Tribe],av_tric)) | G45: =IF($B45="","",COUNTIFS(TblApplications[Tribe],$B45,TblApplications[Action],"Décommissionné",TblApplications[Environnement],av_envc,TblApplications[Domaine],av_domc,TblApplications[Tribe],av_tric)) | H45: =IF($B45="","",SUM(D45:G45)) | K45: =IFERROR(IF(INDEX(TblDomaines[Domaine],12)="","",INDEX(TblDomaines[Domaine],12)),"") | L45: =IF($K45="","",COUNTIFS(TblApplications[Domaine],$K45,TblApplications[Action],"Migré",TblApplications[Environnement],av_envc,TblApplications[Domaine],av_domc,TblApplications[Tribe],av_tric)) | M45: =IF($K45="","",COUNTIFS(TblApplications[Domaine],$K45,TblApplications[Action],"À migrer",TblApplications[Environnement],av_envc,TblApplications[Domaine],av_domc,TblApplications[Tribe],av_tric)) | N45: =IF($K45="","",COUNTIFS(TblApplications[Domaine],$K45,TblApplications[Action],"À décommissionner",TblApplications[Environnement],av_envc,TblApplications[Domaine],av_domc,TblApplications[Tribe],av_tric)) | O45: =IF($K45="","",COUNTIFS(TblApplications[Domaine],$K45,TblApplications[Action],"Décommissionné",TblApplications[Environnement],av_envc,TblApplications[Domaine],av_domc,TblApplications[Tribe],av_tric)) | P45: =IF($K45="","",SUM(L45:O45))
B46: =IFERROR(IF(INDEX(TblTribes[Tribe],13)="","",INDEX(TblTribes[Tribe],13)),"") | C46: =IF($B46="","",INDEX(TblTribes[Domaine de la tribe],13)) | D46: =IF($B46="","",COUNTIFS(TblApplications[Tribe],$B46,TblApplications[Action],"Migré",TblApplications[Environnement],av_envc,TblApplications[Domaine],av_domc,TblApplications[Tribe],av_tric)) | E46: =IF($B46="","",COUNTIFS(TblApplications[Tribe],$B46,TblApplications[Action],"À migrer",TblApplications[Environnement],av_envc,TblApplications[Domaine],av_domc,TblApplications[Tribe],av_tric)) | F46: =IF($B46="","",COUNTIFS(TblApplications[Tribe],$B46,TblApplications[Action],"À décommissionner",TblApplications[Environnement],av_envc,TblApplications[Domaine],av_domc,TblApplications[Tribe],av_tric)) | G46: =IF($B46="","",COUNTIFS(TblApplications[Tribe],$B46,TblApplications[Action],"Décommissionné",TblApplications[Environnement],av_envc,TblApplications[Domaine],av_domc,TblApplications[Tribe],av_tric)) | H46: =IF($B46="","",SUM(D46:G46)) | K46: =IFERROR(IF(INDEX(TblDomaines[Domaine],13)="","",INDEX(TblDomaines[Domaine],13)),"") | L46: =IF($K46="","",COUNTIFS(TblApplications[Domaine],$K46,TblApplications[Action],"Migré",TblApplications[Environnement],av_envc,TblApplications[Domaine],av_domc,TblApplications[Tribe],av_tric)) | M46: =IF($K46="","",COUNTIFS(TblApplications[Domaine],$K46,TblApplications[Action],"À migrer",TblApplications[Environnement],av_envc,TblApplications[Domaine],av_domc,TblApplications[Tribe],av_tric)) | N46: =IF($K46="","",COUNTIFS(TblApplications[Domaine],$K46,TblApplications[Action],"À décommissionner",TblApplications[Environnement],av_envc,TblApplications[Domaine],av_domc,TblApplications[Tribe],av_tric)) | O46: =IF($K46="","",COUNTIFS(TblApplications[Domaine],$K46,TblApplications[Action],"Décommissionné",TblApplications[Environnement],av_envc,TblApplications[Domaine],av_domc,TblApplications[Tribe],av_tric)) | P46: =IF($K46="","",SUM(L46:O46))
B47: =IFERROR(IF(INDEX(TblTribes[Tribe],14)="","",INDEX(TblTribes[Tribe],14)),"") | C47: =IF($B47="","",INDEX(TblTribes[Domaine de la tribe],14)) | D47: =IF($B47="","",COUNTIFS(TblApplications[Tribe],$B47,TblApplications[Action],"Migré",TblApplications[Environnement],av_envc,TblApplications[Domaine],av_domc,TblApplications[Tribe],av_tric)) | E47: =IF($B47="","",COUNTIFS(TblApplications[Tribe],$B47,TblApplications[Action],"À migrer",TblApplications[Environnement],av_envc,TblApplications[Domaine],av_domc,TblApplications[Tribe],av_tric)) | F47: =IF($B47="","",COUNTIFS(TblApplications[Tribe],$B47,TblApplications[Action],"À décommissionner",TblApplications[Environnement],av_envc,TblApplications[Domaine],av_domc,TblApplications[Tribe],av_tric)) | G47: =IF($B47="","",COUNTIFS(TblApplications[Tribe],$B47,TblApplications[Action],"Décommissionné",TblApplications[Environnement],av_envc,TblApplications[Domaine],av_domc,TblApplications[Tribe],av_tric)) | H47: =IF($B47="","",SUM(D47:G47)) | K47: =IFERROR(IF(INDEX(TblDomaines[Domaine],14)="","",INDEX(TblDomaines[Domaine],14)),"") | L47: =IF($K47="","",COUNTIFS(TblApplications[Domaine],$K47,TblApplications[Action],"Migré",TblApplications[Environnement],av_envc,TblApplications[Domaine],av_domc,TblApplications[Tribe],av_tric)) | M47: =IF($K47="","",COUNTIFS(TblApplications[Domaine],$K47,TblApplications[Action],"À migrer",TblApplications[Environnement],av_envc,TblApplications[Domaine],av_domc,TblApplications[Tribe],av_tric)) | N47: =IF($K47="","",COUNTIFS(TblApplications[Domaine],$K47,TblApplications[Action],"À décommissionner",TblApplications[Environnement],av_envc,TblApplications[Domaine],av_domc,TblApplications[Tribe],av_tric)) | O47: =IF($K47="","",COUNTIFS(TblApplications[Domaine],$K47,TblApplications[Action],"Décommissionné",TblApplications[Environnement],av_envc,TblApplications[Domaine],av_domc,TblApplications[Tribe],av_tric)) | P47: =IF($K47="","",SUM(L47:O47))
B48: =IFERROR(IF(INDEX(TblTribes[Tribe],15)="","",INDEX(TblTribes[Tribe],15)),"") | C48: =IF($B48="","",INDEX(TblTribes[Domaine de la tribe],15)) | D48: =IF($B48="","",COUNTIFS(TblApplications[Tribe],$B48,TblApplications[Action],"Migré",TblApplications[Environnement],av_envc,TblApplications[Domaine],av_domc,TblApplications[Tribe],av_tric)) | E48: =IF($B48="","",COUNTIFS(TblApplications[Tribe],$B48,TblApplications[Action],"À migrer",TblApplications[Environnement],av_envc,TblApplications[Domaine],av_domc,TblApplications[Tribe],av_tric)) | F48: =IF($B48="","",COUNTIFS(TblApplications[Tribe],$B48,TblApplications[Action],"À décommissionner",TblApplications[Environnement],av_envc,TblApplications[Domaine],av_domc,TblApplications[Tribe],av_tric)) | G48: =IF($B48="","",COUNTIFS(TblApplications[Tribe],$B48,TblApplications[Action],"Décommissionné",TblApplications[Environnement],av_envc,TblApplications[Domaine],av_domc,TblApplications[Tribe],av_tric)) | H48: =IF($B48="","",SUM(D48:G48)) | K48: =IFERROR(IF(INDEX(TblDomaines[Domaine],15)="","",INDEX(TblDomaines[Domaine],15)),"") | L48: =IF($K48="","",COUNTIFS(TblApplications[Domaine],$K48,TblApplications[Action],"Migré",TblApplications[Environnement],av_envc,TblApplications[Domaine],av_domc,TblApplications[Tribe],av_tric)) | M48: =IF($K48="","",COUNTIFS(TblApplications[Domaine],$K48,TblApplications[Action],"À migrer",TblApplications[Environnement],av_envc,TblApplications[Domaine],av_domc,TblApplications[Tribe],av_tric)) | N48: =IF($K48="","",COUNTIFS(TblApplications[Domaine],$K48,TblApplications[Action],"À décommissionner",TblApplications[Environnement],av_envc,TblApplications[Domaine],av_domc,TblApplications[Tribe],av_tric)) | O48: =IF($K48="","",COUNTIFS(TblApplications[Domaine],$K48,TblApplications[Action],"Décommissionné",TblApplications[Environnement],av_envc,TblApplications[Domaine],av_domc,TblApplications[Tribe],av_tric)) | P48: =IF($K48="","",SUM(L48:O48))
B49: =IFERROR(IF(INDEX(TblTribes[Tribe],16)="","",INDEX(TblTribes[Tribe],16)),"") | C49: =IF($B49="","",INDEX(TblTribes[Domaine de la tribe],16)) | D49: =IF($B49="","",COUNTIFS(TblApplications[Tribe],$B49,TblApplications[Action],"Migré",TblApplications[Environnement],av_envc,TblApplications[Domaine],av_domc,TblApplications[Tribe],av_tric)) | E49: =IF($B49="","",COUNTIFS(TblApplications[Tribe],$B49,TblApplications[Action],"À migrer",TblApplications[Environnement],av_envc,TblApplications[Domaine],av_domc,TblApplications[Tribe],av_tric)) | F49: =IF($B49="","",COUNTIFS(TblApplications[Tribe],$B49,TblApplications[Action],"À décommissionner",TblApplications[Environnement],av_envc,TblApplications[Domaine],av_domc,TblApplications[Tribe],av_tric)) | G49: =IF($B49="","",COUNTIFS(TblApplications[Tribe],$B49,TblApplications[Action],"Décommissionné",TblApplications[Environnement],av_envc,TblApplications[Domaine],av_domc,TblApplications[Tribe],av_tric)) | H49: =IF($B49="","",SUM(D49:G49)) | K49: =IFERROR(IF(INDEX(TblDomaines[Domaine],16)="","",INDEX(TblDomaines[Domaine],16)),"") | L49: =IF($K49="","",COUNTIFS(TblApplications[Domaine],$K49,TblApplications[Action],"Migré",TblApplications[Environnement],av_envc,TblApplications[Domaine],av_domc,TblApplications[Tribe],av_tric)) | M49: =IF($K49="","",COUNTIFS(TblApplications[Domaine],$K49,TblApplications[Action],"À migrer",TblApplications[Environnement],av_envc,TblApplications[Domaine],av_domc,TblApplications[Tribe],av_tric)) | N49: =IF($K49="","",COUNTIFS(TblApplications[Domaine],$K49,TblApplications[Action],"À décommissionner",TblApplications[Environnement],av_envc,TblApplications[Domaine],av_domc,TblApplications[Tribe],av_tric)) | O49: =IF($K49="","",COUNTIFS(TblApplications[Domaine],$K49,TblApplications[Action],"Décommissionné",TblApplications[Environnement],av_envc,TblApplications[Domaine],av_domc,TblApplications[Tribe],av_tric)) | P49: =IF($K49="","",SUM(L49:O49))
B50: =IFERROR(IF(INDEX(TblTribes[Tribe],17)="","",INDEX(TblTribes[Tribe],17)),"") | C50: =IF($B50="","",INDEX(TblTribes[Domaine de la tribe],17)) | D50: =IF($B50="","",COUNTIFS(TblApplications[Tribe],$B50,TblApplications[Action],"Migré",TblApplications[Environnement],av_envc,TblApplications[Domaine],av_domc,TblApplications[Tribe],av_tric)) | E50: =IF($B50="","",COUNTIFS(TblApplications[Tribe],$B50,TblApplications[Action],"À migrer",TblApplications[Environnement],av_envc,TblApplications[Domaine],av_domc,TblApplications[Tribe],av_tric)) | F50: =IF($B50="","",COUNTIFS(TblApplications[Tribe],$B50,TblApplications[Action],"À décommissionner",TblApplications[Environnement],av_envc,TblApplications[Domaine],av_domc,TblApplications[Tribe],av_tric)) | G50: =IF($B50="","",COUNTIFS(TblApplications[Tribe],$B50,TblApplications[Action],"Décommissionné",TblApplications[Environnement],av_envc,TblApplications[Domaine],av_domc,TblApplications[Tribe],av_tric)) | H50: =IF($B50="","",SUM(D50:G50)) | K50: =IFERROR(IF(INDEX(TblDomaines[Domaine],17)="","",INDEX(TblDomaines[Domaine],17)),"") | L50: =IF($K50="","",COUNTIFS(TblApplications[Domaine],$K50,TblApplications[Action],"Migré",TblApplications[Environnement],av_envc,TblApplications[Domaine],av_domc,TblApplications[Tribe],av_tric)) | M50: =IF($K50="","",COUNTIFS(TblApplications[Domaine],$K50,TblApplications[Action],"À migrer",TblApplications[Environnement],av_envc,TblApplications[Domaine],av_domc,TblApplications[Tribe],av_tric)) | N50: =IF($K50="","",COUNTIFS(TblApplications[Domaine],$K50,TblApplications[Action],"À décommissionner",TblApplications[Environnement],av_envc,TblApplications[Domaine],av_domc,TblApplications[Tribe],av_tric)) | O50: =IF($K50="","",COUNTIFS(TblApplications[Domaine],$K50,TblApplications[Action],"Décommissionné",TblApplications[Environnement],av_envc,TblApplications[Domaine],av_domc,TblApplications[Tribe],av_tric)) | P50: =IF($K50="","",SUM(L50:O50))
